Workbook

Sheet Risk Register
E3: Africa CDC Risk Management Register - 2026
B5: Business Unit | C5: Enterprise Risk Theme | D5: Risk Name | E5: Risk Consequence | F5: Root Causes | G5: Risk Type | H5: Likelihood (L) of Risk happening | I5: Score of Likelihood | J5: Impact (I) if Risk happens | K5: Score of Impact | L5: Inherent Risk Score | M5: Mitigation | N5: Management Response | O5: Timeline | P5: Status Update | Q5: Responsible Owner | R5: Action Update | S5: Date of Update | T5: Status Update (colunm N) verified by Africa CDC OIO | U5: Inherent Risk Rating | V5: Mitigation Effectiveness (reviewer assessed) | W5: Residual Likelihood Score | X5: Residual Impact Score | Y5: Residual Risk Score | Z5: Residual Risk Rating | AA5: Risk Movement (Inherent to Residual) | AB5: Rank Helper (Residual, do not edit)
A6: =1 -> 1 | B6: PHC/CHSHP | C6: 2. Workforce sustainability and institutional capability | D6: Short-term contracts for staff with a duration of less than a year and limited forecasting on the renewal plan | E6: If more than 75% of staff have contracts of less than 1 year, then the division faces serious operational disruptions, failure to implement planned activities and impacts on strategic growth of the organization | F6: 1. An absence of comprehensive long-term staffing plan can lead to reliance on short-term contracts without clear renewal strategies. 2. This may stem from project-based staff recruitments, 3. Inadequate HR forecasting of staff needs 4. Short-term project-based programming, which is not sustainable 5. Budget constraints, or a reactive approach to staffing needs that is not matched to the organizational structure. | G6: Operational | H6: Certain | I6: =IFERROR(IF(H6="Unlikely",1,IF(H6="Possible",2,IF(H6="Likely",3,IF(H6="Almost Certain",4,IF(H6="Certain",5,""))))),"") -> 5 | J6: Critical | K6: =IFERROR(IF(J6="Negligible",1,IF(J6="Minor",2,IF(J6="Moderate",3,IF(J6="Major",4,IF(J6="Critical",5,""))))),"") -> 5 | L6: =IF(OR(I6="",K6=""),"",I6*K6) -> 25 | M6: 1. Develop a comprehensive staffing plan that is mapped to available resources, with a clear renewal plan in place. 2. Provide fixed-term contracts with a one-year duration or longer-term contracts, to align with the assumption of duty 3. Create a LOE mechanism across various grants to avoid reliance on the Staff Costs on one funding mechanism, or diversify funding options | O6: 45930 | P6: Open - Extended | Q6: PHC Head of Division HR Senior Leadership | U6: =IF(L6="","",IF(L6<=4,"Low",IF(L6<=9,"Medium",IF(L6<=15,"High","Critical")))) -> Critical | W6: =IF(I6="","",MAX(1,I6-(IF(V6="Limited",1,IF(V6="Partial",2,IF(V6="Substantial",3,IF(V6="Highly Effective",4,0))))))) -> 5 | X6: =IF(K6="","",MAX(1,K6-ROUNDDOWN((IF(V6="Limited",1,IF(V6="Partial",2,IF(V6="Substantial",3,IF(V6="Highly Effective",4,0)))))/2,0))) -> 5 | Y6: =IF(OR(W6="",X6=""),"",W6*X6) -> 25 | Z6: =IF(Y6="","",IF(Y6<=4,"Low",IF(Y6<=9,"Medium",IF(Y6<=15,"High","Critical")))) -> Critical | AA6: =IF(OR(L6="",Y6=""),"",IF(Y6<L6,"Reduced by "&(L6-Y6)&" pts",IF(Y6=L6,"No Change","Increased by "&(Y6-L6)&" pts"))) -> No Change | AB6: =IF(Y6="","",Y6+(ROW()/10000000)) -> 25.000001
A7: =1+1 -> 2 | B7: PHC/CHSHP | C7: 1. Sustainable financing and resource mobilization | D7: Inadequate funding for programme implementation | E7: If the centre/division has inadequate funding for programme implementation, then the organisation will not be able to deliver on its mandate, thereby damaging the organisation's reputation | F7: 1. Lack of comprehensive financial planning that accurately estimates the funding needed for the entire program lifecycle. 2. Ineffective proposal writing or failure to meet funding application requirements, resulting in unsuccessful grant applications. 3. Insufficient divisional or organizational budget due to competing priorities or budget cuts. 4. Poor forecasting or planning that underestimates the actual funding needs. 5. Dependence on unreliable or unpredictable funding sources such as grants. 6. Misallocation of funds or delays in disbursing available resources. 7. Over-reliance on a single funding stream makes the organization vulnerable to funding cuts | G7: Reputational | H7: Almost Certain | I7: =IFERROR(IF(H7="Unlikely",1,IF(H7="Possible",2,IF(H7="Likely",3,IF(H7="Almost Certain",4,IF(H7="Certain",5,""))))),"") -> 4 | J7: Critical | K7: =IFERROR(IF(J7="Negligible",1,IF(J7="Minor",2,IF(J7="Moderate",3,IF(J7="Major",4,IF(J7="Critical",5,""))))),"") -> 5 | L7: =IF(OR(I7="",K7=""),"",I7*K7) -> 20 | M7: 1. Conduct thorough needs assessments and realistic budgeting, including implementing rolling forecasts to adapt to changing contexts. 2. Diversify funding sources through strengthening partnerships, sponsorships, and relationships with a broader range of donors and stakeholders. 3. Improve financial management through regular financial monitoring and reporting to ensure efficient use of resources. Also, identify and eliminate waste or inefficiencies. 4. Build strong relationships to secure ongoing support 5. Ensure transparency and accountability to build trust with funders. 6. Leverage technology and innovation for effective use digital tools for efficient programme management and reporting | O7: 45930 | P7: Open - Extended | Q7: PHC Center Director Head of Division | U7: =IF(L7="","",IF(L7<=4,"Low",IF(L7<=9,"Medium",IF(L7<=15,"High","Critical")))) -> Critical | W7: =IF(I7="","",MAX(1,I7-(IF(V7="Limited",1,IF(V7="Partial",2,IF(V7="Substantial",3,IF(V7="Highly Effective",4,0))))))) -> 4 | X7: =IF(K7="","",MAX(1,K7-ROUNDDOWN((IF(V7="Limited",1,IF(V7="Partial",2,IF(V7="Substantial",3,IF(V7="Highly Effective",4,0)))))/2,0))) -> 5 | Y7: =IF(OR(W7="",X7=""),"",W7*X7) -> 20 | Z7: =IF(Y7="","",IF(Y7<=4,"Low",IF(Y7<=9,"Medium",IF(Y7<=15,"High","Critical")))) -> Critical | AA7: =IF(OR(L7="",Y7=""),"",IF(Y7<L7,"Reduced by "&(L7-Y7)&" pts",IF(Y7=L7,"No Change","Increased by "&(Y7-L7)&" pts"))) -> No Change | AB7: =IF(Y7="","",Y7+(ROW()/10000000)) -> 20.000001
A8: =1+2 -> 3 | B8: PHC/CHSHP | C8: 2. Workforce sustainability and institutional capability | D8: Loss of institutional memory and capacity | E8: If there are frequent resignations or attrition of experienced personnel, coupled with an informal knowledge transfer mechanism and limited knowledge management practices, then there will be a loss of institutional memory, which may lead to inadequate productivity and increased operational costs | F8: 1. Lack of effective staff retention strategies 2. Informal or nonexistent knowledge transfer protocols 3. Limited or poorly implemented knowledge management systems 4. Organizational culture that does not prioritize knowledge sharing | G8: Operational | H8: Likely | I8: =IFERROR(IF(H8="Unlikely",1,IF(H8="Possible",2,IF(H8="Likely",3,IF(H8="Almost Certain",4,IF(H8="Certain",5,""))))),"") -> 3 | J8: Major | K8: =IFERROR(IF(J8="Negligible",1,IF(J8="Minor",2,IF(J8="Moderate",3,IF(J8="Major",4,IF(J8="Critical",5,""))))),"") -> 4 | L8: =IF(OR(I8="",K8=""),"",I8*K8) -> 12 | M8: 1. Promote a positive, inclusive, and engaging workplace culture. 2. Document roles, responsibilities, and critical knowledge during onboarding and exit interviews. 3. Implement Knowledge Management Systems such as centralized knowledge repositories like intranet, shared drives, or specialized knowledge management software to store institutional knowledge together with collaboration tools like SharePoint, for ongoing knowledge sharing. 4. Foster a culture of knowledge sharing to promote transparency and collaboration. | O8: 45930 | P8: Open - Extended | Q8: PHC Centre Director Head of Division | U8: =IF(L8="","",IF(L8<=4,"Low",IF(L8<=9,"Medium",IF(L8<=15,"High","Critical")))) -> High | W8: =IF(I8="","",MAX(1,I8-(IF(V8="Limited",1,IF(V8="Partial",2,IF(V8="Substantial",3,IF(V8="Highly Effective",4,0))))))) -> 3 | X8: =IF(K8="","",MAX(1,K8-ROUNDDOWN((IF(V8="Limited",1,IF(V8="Partial",2,IF(V8="Substantial",3,IF(V8="Highly Effective",4,0)))))/2,0))) -> 4 | Y8: =IF(OR(W8="",X8=""),"",W8*X8) -> 12 | Z8: =IF(Y8="","",IF(Y8<=4,"Low",IF(Y8<=9,"Medium",IF(Y8<=15,"High","Critical")))) -> High | AA8: =IF(OR(L8="",Y8=""),"",IF(Y8<L8,"Reduced by "&(L8-Y8)&" pts",IF(Y8=L8,"No Change","Increased by "&(Y8-L8)&" pts"))) -> No Change | AB8: =IF(Y8="","",Y8+(ROW()/10000000)) -> 12.000001
A9: 4 | B9: PHC/CHSHP | C9: 4. Program execution and delivery | D9: Inadequate internal programmatic alignment to the overall PHC structure & silo implementation | E9: If there is inadequate internal programmatic alignment with the overall PHC structure, then there will be duplication of efforts, verticalisation, and fragmentation of support to member states, which increases administrative costs and undermines the effectiveness of the PHC centre to demonstrate results towards achievement of the African Continental targets | F9: 1. Lack of interdisciplinary teamwork and shared objectives 2. Divisions/ Units/ Teams operate in silo, with limited coordination, collaboration, integrated strategies undermining the integrated PHC approach | G9: Strategic | H9: Likely | I9: =IFERROR(IF(H9="Unlikely",1,IF(H9="Possible",2,IF(H9="Likely",3,IF(H9="Almost Certain",4,IF(H9="Certain",5,""))))),"") -> 3 | J9: Critical | K9: =IFERROR(IF(J9="Negligible",1,IF(J9="Minor",2,IF(J9="Moderate",3,IF(J9="Major",4,IF(J9="Critical",5,""))))),"") -> 5 | L9: =IF(OR(I9="",K9=""),"",I9*K9) -> 15 | M9: 1. Create a comprehensive strategic plan that clearly links all units’ activities to the overarching goals and targets 2. Joint Planning, Regular Meetings, Joint Reviews, Shared Platforms, and Reporting Systems to foster collaboration, transparency, coordination and accountability 3. Regularly assess activities for overlaps, gaps, and alignment; use findings to adjust strategies and budgets that support integrated activities rather than fragmented efforts. | O9: 45930 | P9: Open - Extended | Q9: PHC Centre Director | U9: =IF(L9="","",IF(L9<=4,"Low",IF(L9<=9,"Medium",IF(L9<=15,"High","Critical")))) -> High | W9: =IF(I9="","",MAX(1,I9-(IF(V9="Limited",1,IF(V9="Partial",2,IF(V9="Substantial",3,IF(V9="Highly Effective",4,0))))))) -> 3 | X9: =IF(K9="","",MAX(1,K9-ROUNDDOWN((IF(V9="Limited",1,IF(V9="Partial",2,IF(V9="Substantial",3,IF(V9="Highly Effective",4,0)))))/2,0))) -> 5 | Y9: =IF(OR(W9="",X9=""),"",W9*X9) -> 15 | Z9: =IF(Y9="","",IF(Y9<=4,"Low",IF(Y9<=9,"Medium",IF(Y9<=15,"High","Critical")))) -> High | AA9: =IF(OR(L9="",Y9=""),"",IF(Y9<L9,"Reduced by "&(L9-Y9)&" pts",IF(Y9=L9,"No Change","Increased by "&(Y9-L9)&" pts"))) -> No Change | AB9: =IF(Y9="","",Y9+(ROW()/10000000)) -> 15.000001
A10: 5 | B10: PHC/CHSHP | C10: 3. Fiduciary stewardship and internal control | D10: Delays in disbursements of funds for the implementation of activities due to several approval levels and the absence of approval thresholds | E10: If there are delays in disbursement of funds, then there will be delayed implementation of planned activities which may result in failure to meet promised targets, leading to organizational reputation risk and reduced funding opportunities | F10: Multiple approval layers or hierarchical review stages that slow down the disbursement process due to a lack of clear delegation of authority, leading to delays in decision-making | G10: Reputational | H10: Almost Certain | I10: =IFERROR(IF(H10="Unlikely",1,IF(H10="Possible",2,IF(H10="Likely",3,IF(H10="Almost Certain",4,IF(H10="Certain",5,""))))),"") -> 4 | J10: Critical | K10: =IFERROR(IF(J10="Negligible",1,IF(J10="Minor",2,IF(J10="Moderate",3,IF(J10="Major",4,IF(J10="Critical",5,""))))),"") -> 5 | L10: =IF(OR(I10="",K10=""),"",I10*K10) -> 20 | M10: 1. Establish a clear Delegation of Authority (DoA) Framework,clearly specifying approval limits based on transaction size and risk level. Map out who can approve what to reduce unnecessary layers. Document authority levels and ensure all parties understand their decision-making scope. 2. Strengthen Automated Workflow and Approval Systems for workflow routing of approval requests based on predefined DoA, and set automatic escalation protocols with real-time tracking for transparency and quick identification of approval delays 3. Set Key Performance Indicators (KPIs) and Accountability to track approval turnaround times and hold approvers accountable for unnecessary delays to foster responsibility 4. Enhance the existing Rapid-Approval Protocol for quick approval pathways of urgent disbursements to prevent reputational damage | O10: 45930 | P10: Open - Extended | Q10: Senior Leadership | U10: =IF(L10="","",IF(L10<=4,"Low",IF(L10<=9,"Medium",IF(L10<=15,"High","Critical")))) -> Critical | W10: =IF(I10="","",MAX(1,I10-(IF(V10="Limited",1,IF(V10="Partial",2,IF(V10="Substantial",3,IF(V10="Highly Effective",4,0))))))) -> 4 | X10: =IF(K10="","",MAX(1,K10-ROUNDDOWN((IF(V10="Limited",1,IF(V10="Partial",2,IF(V10="Substantial",3,IF(V10="Highly Effective",4,0)))))/2,0))) -> 5 | Y10: =IF(OR(W10="",X10=""),"",W10*X10) -> 20 | Z10: =IF(Y10="","",IF(Y10<=4,"Low",IF(Y10<=9,"Medium",IF(Y10<=15,"High","Critical")))) -> Critical | AA10: =IF(OR(L10="",Y10=""),"",IF(Y10<L10,"Reduced by "&(L10-Y10)&" pts",IF(Y10=L10,"No Change","Increased by "&(Y10-L10)&" pts"))) -> No Change | AB10: =IF(Y10="","",Y10+(ROW()/10000000)) -> 20.000001
A11: 6 | B11: PHC/CHSHP | C11: 1. Sustainable financing and resource mobilization | D11: Impact of ODA Cuts on community health initiatives on the African continent | E11: If recent geopolitical shifts and changing donor priorities continue, then it will lead to significant cuts in ODA allocated to health programs, this reduction results in decreased funding for community health initiatives. | F11: 1. Changes in donor countries' political priorities or economic downturns can lead to reduced ODA budgets, including the diversion of funding away from health initiatives due to geopolitical conflicts. 2. Limited domestic resources and weak fiscal capacity in recipient countries make them heavily reliant on ODA for community health programs, which is compounded by a lack of sustainable financing mechanisms within member states. 3. Donor agencies often set priorities based on their strategic interests, which may not align with local health needs 4. Poor integration of community health services into national health systems, making programs vulnerable when external funding decreases. | G11: Contextual | H11: Almost Certain | I11: =IFERROR(IF(H11="Unlikely",1,IF(H11="Possible",2,IF(H11="Likely",3,IF(H11="Almost Certain",4,IF(H11="Certain",5,""))))),"") -> 4 | J11: Critical | K11: =IFERROR(IF(J11="Negligible",1,IF(J11="Minor",2,IF(J11="Moderate",3,IF(J11="Major",4,IF(J11="Critical",5,""))))),"") -> 5 | L11: =IF(OR(I11="",K11=""),"",I11*K11) -> 20 | M11: 1. Encourage governments to increase domestic budget allocations for health, including innovative financing mechanisms like health taxes to fund CH initiatives 2. Continue advocacy on embedding community health initiatives into national health systems to ensure continuity regardless of external funding fluctuations and shift investment to local health workforce training, infrastructure, and supply chains to improve self-sufficiency 3. Diversify Funding Sources and Donor Engagement for funding from a variety of sources, including the private sector, philanthropic organizations, and regional bodies & forster multi-stakeholder coordination, including rebranding the strategic approach | O11: 45930 | P11: Open - Extended | Q11: PHC Centre Director | U11: =IF(L11="","",IF(L11<=4,"Low",IF(L11<=9,"Medium",IF(L11<=15,"High","Critical")))) -> Critical | W11: =IF(I11="","",MAX(1,I11-(IF(V11="Limited",1,IF(V11="Partial",2,IF(V11="Substantial",3,IF(V11="Highly Effective",4,0))))))) -> 4 | X11: =IF(K11="","",MAX(1,K11-ROUNDDOWN((IF(V11="Limited",1,IF(V11="Partial",2,IF(V11="Substantial",3,IF(V11="Highly Effective",4,0)))))/2,0))) -> 5 | Y11: =IF(OR(W11="",X11=""),"",W11*X11) -> 20 | Z11: =IF(Y11="","",IF(Y11<=4,"Low",IF(Y11<=9,"Medium",IF(Y11<=15,"High","Critical")))) -> Critical | AA11: =IF(OR(L11="",Y11=""),"",IF(Y11<L11,"Reduced by "&(L11-Y11)&" pts",IF(Y11=L11,"No Change","Increased by "&(Y11-L11)&" pts"))) -> No Change | AB11: =IF(Y11="","",Y11+(ROW()/10000000)) -> 20.000001
A12: 7 | B12: PHC/IDDS | C12: 5. Country, partner, and geopolitical context | D12: Member states become non-collaborative after Africa CDC shows no responses to their request for assistance | E12: If the Division is not capable to respond to various requests outside of the donor mandated activities, then this could affect the credibilty of the organization with regard to his goal and commitment | F12: Insufficient resource mobilization Insufficient workforce in the division | G12: Reputational | H12: Certain | I12: =IFERROR(IF(H12="Unlikely",1,IF(H12="Possible",2,IF(H12="Likely",3,IF(H12="Almost Certain",4,IF(H12="Certain",5,""))))),"") -> 5 | J12: Critical | K12: =IFERROR(IF(J12="Negligible",1,IF(J12="Minor",2,IF(J12="Moderate",3,IF(J12="Major",4,IF(J12="Critical",5,""))))),"") -> 5 | L12: =IF(OR(I12="",K12=""),"",I12*K12) -> 25 | M12: Diversified and expanded resource mobilization to support long term implementation of integrated activities | O12: 45930 | P12: Open - Extended | Q12: Center Director at PHC/ Human Resource vision | U12: =IF(L12="","",IF(L12<=4,"Low",IF(L12<=9,"Medium",IF(L12<=15,"High","Critical")))) -> Critical | W12: =IF(I12="","",MAX(1,I12-(IF(V12="Limited",1,IF(V12="Partial",2,IF(V12="Substantial",3,IF(V12="Highly Effective",4,0))))))) -> 5 | X12: =IF(K12="","",MAX(1,K12-ROUNDDOWN((IF(V12="Limited",1,IF(V12="Partial",2,IF(V12="Substantial",3,IF(V12="Highly Effective",4,0)))))/2,0))) -> 5 | Y12: =IF(OR(W12="",X12=""),"",W12*X12) -> 25 | Z12: =IF(Y12="","",IF(Y12<=4,"Low",IF(Y12<=9,"Medium",IF(Y12<=15,"High","Critical")))) -> Critical | AA12: =IF(OR(L12="",Y12=""),"",IF(Y12<L12,"Reduced by "&(L12-Y12)&" pts",IF(Y12=L12,"No Change","Increased by "&(Y12-L12)&" pts"))) -> No Change | AB12: =IF(Y12="","",Y12+(ROW()/10000000)) -> 25.000001
A13: 8 | B13: PHC/IDDS | C13: 2. Workforce sustainability and institutional capability | D13: Loss of operational continuity due to high staff turn-over | E13: if the division continues to rely on high staff turn-over, then this could affect continuity and efficacity of activities implementation | F13: Length process of recruitment, uncertainty of grant fund, and shift in financial resource | G13: Operational | H13: Certain | I13: =IFERROR(IF(H13="Unlikely",1,IF(H13="Possible",2,IF(H13="Likely",3,IF(H13="Almost Certain",4,IF(H13="Certain",5,""))))),"") -> 5 | J13: Major | K13: =IFERROR(IF(J13="Negligible",1,IF(J13="Minor",2,IF(J13="Moderate",3,IF(J13="Major",4,IF(J13="Critical",5,""))))),"") -> 4 | L13: =IF(OR(I13="",K13=""),"",I13*K13) -> 20 | M13: Expanded resource mobilization Expedited recruitment process | O13: 45930 | P13: Open - Extended | Q13: Center Director at PHC / Partnership at External Relations | U13: =IF(L13="","",IF(L13<=4,"Low",IF(L13<=9,"Medium",IF(L13<=15,"High","Critical")))) -> Critical | W13: =IF(I13="","",MAX(1,I13-(IF(V13="Limited",1,IF(V13="Partial",2,IF(V13="Substantial",3,IF(V13="Highly Effective",4,0))))))) -> 5 | X13: =IF(K13="","",MAX(1,K13-ROUNDDOWN((IF(V13="Limited",1,IF(V13="Partial",2,IF(V13="Substantial",3,IF(V13="Highly Effective",4,0)))))/2,0))) -> 4 | Y13: =IF(OR(W13="",X13=""),"",W13*X13) -> 20 | Z13: =IF(Y13="","",IF(Y13<=4,"Low",IF(Y13<=9,"Medium",IF(Y13<=15,"High","Critical")))) -> Critical | AA13: =IF(OR(L13="",Y13=""),"",IF(Y13<L13,"Reduced by "&(L13-Y13)&" pts",IF(Y13=L13,"No Change","Increased by "&(Y13-L13)&" pts"))) -> No Change | AB13: =IF(Y13="","",Y13+(ROW()/10000000)) -> 20.000001
A14: 9 | B14: PHC/IDDS | C14: 4. Program execution and delivery | D14: Difficult collaboration with other ACDC centers in order to share knowledge and ensure internal alignment on critical projects | E14: If the division continues to relay only on itself, then this could affect the quality, relevance and delays in delivering interventions | F14: Corporate culture Lack of formal frameworks to foster inter-center collaboration | G14: Operational | H14: Likely | I14: =IFERROR(IF(H14="Unlikely",1,IF(H14="Possible",2,IF(H14="Likely",3,IF(H14="Almost Certain",4,IF(H14="Certain",5,""))))),"") -> 3 | J14: Major | K14: =IFERROR(IF(J14="Negligible",1,IF(J14="Minor",2,IF(J14="Moderate",3,IF(J14="Major",4,IF(J14="Critical",5,""))))),"") -> 4 | L14: =IF(OR(I14="",K14=""),"",I14*K14) -> 12 | M14: Instaurer un cadre de collaboration continu inter-centres | O14: 45930 | P14: Open - Extended | Q14: Center Director at PHC | U14: =IF(L14="","",IF(L14<=4,"Low",IF(L14<=9,"Medium",IF(L14<=15,"High","Critical")))) -> High | W14: =IF(I14="","",MAX(1,I14-(IF(V14="Limited",1,IF(V14="Partial",2,IF(V14="Substantial",3,IF(V14="Highly Effective",4,0))))))) -> 3 | X14: =IF(K14="","",MAX(1,K14-ROUNDDOWN((IF(V14="Limited",1,IF(V14="Partial",2,IF(V14="Substantial",3,IF(V14="Highly Effective",4,0)))))/2,0))) -> 4 | Y14: =IF(OR(W14="",X14=""),"",W14*X14) -> 12 | Z14: =IF(Y14="","",IF(Y14<=4,"Low",IF(Y14<=9,"Medium",IF(Y14<=15,"High","Critical")))) -> High | AA14: =IF(OR(L14="",Y14=""),"",IF(Y14<L14,"Reduced by "&(L14-Y14)&" pts",IF(Y14=L14,"No Change","Increased by "&(Y14-L14)&" pts"))) -> No Change | AB14: =IF(Y14="","",Y14+(ROW()/10000000)) -> 12.000001
A15: 10 | B15: PHC/IDDS | C15: 9. Emergency readiness, duty of care, and biosafety/biosecurity | D15: Unsafe pratices: technical staffs have to travel from headquarters with a lot of CASH to support activities in ME | E15: If the organization continues to relay of unsafe practices regarding finances, then this could impact it's safety staff and finances | F15: Limitation options due to complicated processes | G15: Operational | H15: Certain | I15: =IFERROR(IF(H15="Unlikely",1,IF(H15="Possible",2,IF(H15="Likely",3,IF(H15="Almost Certain",4,IF(H15="Certain",5,""))))),"") -> 5 | J15: Critical | K15: =IFERROR(IF(J15="Negligible",1,IF(J15="Minor",2,IF(J15="Moderate",3,IF(J15="Major",4,IF(J15="Critical",5,""))))),"") -> 5 | L15: =IF(OR(I15="",K15=""),"",I15*K15) -> 25 | M15: Relax procedures: involve RCCs or national coordinators in the management of financial flows or send money to the MOH. | O15: 45930 | P15: Open - Extended | Q15: Finances | U15: =IF(L15="","",IF(L15<=4,"Low",IF(L15<=9,"Medium",IF(L15<=15,"High","Critical")))) -> Critical | W15: =IF(I15="","",MAX(1,I15-(IF(V15="Limited",1,IF(V15="Partial",2,IF(V15="Substantial",3,IF(V15="Highly Effective",4,0))))))) -> 5 | X15: =IF(K15="","",MAX(1,K15-ROUNDDOWN((IF(V15="Limited",1,IF(V15="Partial",2,IF(V15="Substantial",3,IF(V15="Highly Effective",4,0)))))/2,0))) -> 5 | Y15: =IF(OR(W15="",X15=""),"",W15*X15) -> 25 | Z15: =IF(Y15="","",IF(Y15<=4,"Low",IF(Y15<=9,"Medium",IF(Y15<=15,"High","Critical")))) -> Critical | AA15: =IF(OR(L15="",Y15=""),"",IF(Y15<L15,"Reduced by "&(L15-Y15)&" pts",IF(Y15=L15,"No Change","Increased by "&(Y15-L15)&" pts"))) -> No Change | AB15: =IF(Y15="","",Y15+(ROW()/10000000)) -> 25.000001
A16: 11 | B16: SRMNCAH | C16: 2. Workforce sustainability and institutional capability | D16: Short contract of staff | E16: Pause of programme activities | F16: Limited budget to cover staff cost | G16: Project | H16: Certain | I16: =IFERROR(IF(H16="Unlikely",1,IF(H16="Possible",2,IF(H16="Likely",3,IF(H16="Almost Certain",4,IF(H16="Certain",5,""))))),"") -> 5 | J16: Critical | K16: =IFERROR(IF(J16="Negligible",1,IF(J16="Minor",2,IF(J16="Moderate",3,IF(J16="Major",4,IF(J16="Critical",5,""))))),"") -> 5 | L16: =IF(OR(I16="",K16=""),"",I16*K16) -> 25 | O16: 45930 | P16: Open - Extended | U16: =IF(L16="","",IF(L16<=4,"Low",IF(L16<=9,"Medium",IF(L16<=15,"High","Critical")))) -> Critical | W16: =IF(I16="","",MAX(1,I16-(IF(V16="Limited",1,IF(V16="Partial",2,IF(V16="Substantial",3,IF(V16="Highly Effective",4,0))))))) -> 5 | X16: =IF(K16="","",MAX(1,K16-ROUNDDOWN((IF(V16="Limited",1,IF(V16="Partial",2,IF(V16="Substantial",3,IF(V16="Highly Effective",4,0)))))/2,0))) -> 5 | Y16: =IF(OR(W16="",X16=""),"",W16*X16) -> 25 | Z16: =IF(Y16="","",IF(Y16<=4,"Low",IF(Y16<=9,"Medium",IF(Y16<=15,"High","Critical")))) -> Critical | AA16: =IF(OR(L16="",Y16=""),"",IF(Y16<L16,"Reduced by "&(L16-Y16)&" pts",IF(Y16=L16,"No Change","Increased by "&(Y16-L16)&" pts"))) -> No Change | AB16: =IF(Y16="","",Y16+(ROW()/10000000)) -> 25.000002
A17: 12 | B17: SRNMCAH | C17: 1. Sustainable financing and resource mobilization | D17: Priorities annual new activity delaly | E17: Slow progress on the implementation of RMNH unit annual priorities | F17: No funding to fund activities | G17: Operational | H17: Almost Certain | I17: =IFERROR(IF(H17="Unlikely",1,IF(H17="Possible",2,IF(H17="Likely",3,IF(H17="Almost Certain",4,IF(H17="Certain",5,""))))),"") -> 4 | J17: Major | K17: =IFERROR(IF(J17="Negligible",1,IF(J17="Minor",2,IF(J17="Moderate",3,IF(J17="Major",4,IF(J17="Critical",5,""))))),"") -> 4 | L17: =IF(OR(I17="",K17=""),"",I17*K17) -> 16 | O17: 45930 | P17: Open - Extended | U17: =IF(L17="","",IF(L17<=4,"Low",IF(L17<=9,"Medium",IF(L17<=15,"High","Critical")))) -> Critical | W17: =IF(I17="","",MAX(1,I17-(IF(V17="Limited",1,IF(V17="Partial",2,IF(V17="Substantial",3,IF(V17="Highly Effective",4,0))))))) -> 4 | X17: =IF(K17="","",MAX(1,K17-ROUNDDOWN((IF(V17="Limited",1,IF(V17="Partial",2,IF(V17="Substantial",3,IF(V17="Highly Effective",4,0)))))/2,0))) -> 4 | Y17: =IF(OR(W17="",X17=""),"",W17*X17) -> 16 | Z17: =IF(Y17="","",IF(Y17<=4,"Low",IF(Y17<=9,"Medium",IF(Y17<=15,"High","Critical")))) -> Critical | AA17: =IF(OR(L17="",Y17=""),"",IF(Y17<L17,"Reduced by "&(L17-Y17)&" pts",IF(Y17=L17,"No Change","Increased by "&(Y17-L17)&" pts"))) -> No Change | AB17: =IF(Y17="","",Y17+(ROW()/10000000)) -> 16.000002
A18: 13 | B18: SRNMCAH | C18: 4. Program execution and delivery | D18: Non-alignment of the different units of the division | G18: Strategic | H18: Likely | I18: =IFERROR(IF(H18="Unlikely",1,IF(H18="Possible",2,IF(H18="Likely",3,IF(H18="Almost Certain",4,IF(H18="Certain",5,""))))),"") -> 3 | J18: Major | K18: =IFERROR(IF(J18="Negligible",1,IF(J18="Minor",2,IF(J18="Moderate",3,IF(J18="Major",4,IF(J18="Critical",5,""))))),"") -> 4 | L18: =IF(OR(I18="",K18=""),"",I18*K18) -> 12 | O18: 45930 | P18: Open - Extended | U18: =IF(L18="","",IF(L18<=4,"Low",IF(L18<=9,"Medium",IF(L18<=15,"High","Critical")))) -> High | W18: =IF(I18="","",MAX(1,I18-(IF(V18="Limited",1,IF(V18="Partial",2,IF(V18="Substantial",3,IF(V18="Highly Effective",4,0))))))) -> 3 | X18: =IF(K18="","",MAX(1,K18-ROUNDDOWN((IF(V18="Limited",1,IF(V18="Partial",2,IF(V18="Substantial",3,IF(V18="Highly Effective",4,0)))))/2,0))) -> 4 | Y18: =IF(OR(W18="",X18=""),"",W18*X18) -> 12 | Z18: =IF(Y18="","",IF(Y18<=4,"Low",IF(Y18<=9,"Medium",IF(Y18<=15,"High","Critical")))) -> High | AA18: =IF(OR(L18="",Y18=""),"",IF(Y18<L18,"Reduced by "&(L18-Y18)&" pts",IF(Y18=L18,"No Change","Increased by "&(Y18-L18)&" pts"))) -> No Change | AB18: =IF(Y18="","",Y18+(ROW()/10000000)) -> 12.000002
A19: 14 | B19: PHC/NCDIMH | C19: 2. Workforce sustainability and institutional capability | D19: Inadequate staff to effectively deliver on division goal | F19: need for additional staff to cover the prgrammes and projects delivered by the division | G19: Operational | H19: Possible | I19: =IFERROR(IF(H19="Unlikely",1,IF(H19="Possible",2,IF(H19="Likely",3,IF(H19="Almost Certain",4,IF(H19="Certain",5,""))))),"") -> 2 | J19: Minor | K19: =IFERROR(IF(J19="Negligible",1,IF(J19="Minor",2,IF(J19="Moderate",3,IF(J19="Major",4,IF(J19="Critical",5,""))))),"") -> 2 | L19: =IF(OR(I19="",K19=""),"",I19*K19) -> 4 | M19: Resource mobilization to meet staff costs and advocate for Member States Funding | O19: 45930 | P19: Open - Extended | U19: =IF(L19="","",IF(L19<=4,"Low",IF(L19<=9,"Medium",IF(L19<=15,"High","Critical")))) -> Low | W19: =IF(I19="","",MAX(1,I19-(IF(V19="Limited",1,IF(V19="Partial",2,IF(V19="Substantial",3,IF(V19="Highly Effective",4,0))))))) -> 2 | X19: =IF(K19="","",MAX(1,K19-ROUNDDOWN((IF(V19="Limited",1,IF(V19="Partial",2,IF(V19="Substantial",3,IF(V19="Highly Effective",4,0)))))/2,0))) -> 2 | Y19: =IF(OR(W19="",X19=""),"",W19*X19) -> 4 | Z19: =IF(Y19="","",IF(Y19<=4,"Low",IF(Y19<=9,"Medium",IF(Y19<=15,"High","Critical")))) -> Low | AA19: =IF(OR(L19="",Y19=""),"",IF(Y19<L19,"Reduced by "&(L19-Y19)&" pts",IF(Y19=L19,"No Change","Increased by "&(Y19-L19)&" pts"))) -> No Change | AB19: =IF(Y19="","",Y19+(ROW()/10000000)) -> 4.0000019
A20: 15 | B20: PHC/NCDIMH | C20: 2. Workforce sustainability and institutional capability | D20: Short-term contract for recruited staff | E20: If majority of staff have short term contracts of less than 2 years, then the division faces operational challenges leading to disturbances in implementation of planned activities and impacts on the organizational mandate. | F20: Limited budget to cover staff cost and budgets being avaialbel on annual basis. | G20: Operational | H20: Almost Certain | I20: =IFERROR(IF(H20="Unlikely",1,IF(H20="Possible",2,IF(H20="Likely",3,IF(H20="Almost Certain",4,IF(H20="Certain",5,""))))),"") -> 4 | J20: Major | K20: =IFERROR(IF(J20="Negligible",1,IF(J20="Minor",2,IF(J20="Moderate",3,IF(J20="Major",4,IF(J20="Critical",5,""))))),"") -> 4 | L20: =IF(OR(I20="",K20=""),"",I20*K20) -> 16 | M20: To negotiate for long-term staff contracts according to funding availability and have extended grants | O20: 45930 | P20: Open - Extended | Q20: PHC Centre Director, HR Director and Director of Strategic Operation | U20: =IF(L20="","",IF(L20<=4,"Low",IF(L20<=9,"Medium",IF(L20<=15,"High","Critical")))) -> Critical | W20: =IF(I20="","",MAX(1,I20-(IF(V20="Limited",1,IF(V20="Partial",2,IF(V20="Substantial",3,IF(V20="Highly Effective",4,0))))))) -> 4 | X20: =IF(K20="","",MAX(1,K20-ROUNDDOWN((IF(V20="Limited",1,IF(V20="Partial",2,IF(V20="Substantial",3,IF(V20="Highly Effective",4,0)))))/2,0))) -> 4 | Y20: =IF(OR(W20="",X20=""),"",W20*X20) -> 16 | Z20: =IF(Y20="","",IF(Y20<=4,"Low",IF(Y20<=9,"Medium",IF(Y20<=15,"High","Critical")))) -> Critical | AA20: =IF(OR(L20="",Y20=""),"",IF(Y20<L20,"Reduced by "&(L20-Y20)&" pts",IF(Y20=L20,"No Change","Increased by "&(Y20-L20)&" pts"))) -> No Change | AB20: =IF(Y20="","",Y20+(ROW()/10000000)) -> 16.000002
A21: 16 | B21: PHC/NCDIMH | C21: 4. Program execution and delivery | D21: Misalignment between the NCDIMH division and other divisions under PHC | E21: If there is inadequate internal alignment with the overall PHC structure, then there will be duplication of efforts, verticalisation, and fragmentation of support to member states and the succefull implentation of programmes which increases administrative costs, indicate silo working ethic and undermines the effectiveness of the PHC centre . | F21: 1. Lack of interdisciplinary teamwork and shared objectives 2. Divisions/ Units/ Teams operate in isolation, with limited coordination or collaboration undermining the integrated PHC approach 3. lack of technical meeting between divisions under PHC for aligning and do cross division support. | G21: Strategic | H21: Likely | I21: =IFERROR(IF(H21="Unlikely",1,IF(H21="Possible",2,IF(H21="Likely",3,IF(H21="Almost Certain",4,IF(H21="Certain",5,""))))),"") -> 3 | J21: Moderate | K21: =IFERROR(IF(J21="Negligible",1,IF(J21="Minor",2,IF(J21="Moderate",3,IF(J21="Major",4,IF(J21="Critical",5,""))))),"") -> 3 | L21: =IF(OR(I21="",K21=""),"",I21*K21) -> 9 | M21: Establish/Introducing weekly PHC technical meetings for Divisions to share updates and create Programmatic communication SOP. | O21: 45930 | P21: Open - Extended | Q21: PHC Centre Director and Heads of Divisions | U21: =IF(L21="","",IF(L21<=4,"Low",IF(L21<=9,"Medium",IF(L21<=15,"High","Critical")))) -> Medium | W21: =IF(I21="","",MAX(1,I21-(IF(V21="Limited",1,IF(V21="Partial",2,IF(V21="Substantial",3,IF(V21="Highly Effective",4,0))))))) -> 3 | X21: =IF(K21="","",MAX(1,K21-ROUNDDOWN((IF(V21="Limited",1,IF(V21="Partial",2,IF(V21="Substantial",3,IF(V21="Highly Effective",4,0)))))/2,0))) -> 3 | Y21: =IF(OR(W21="",X21=""),"",W21*X21) -> 9 | Z21: =IF(Y21="","",IF(Y21<=4,"Low",IF(Y21<=9,"Medium",IF(Y21<=15,"High","Critical")))) -> Medium | AA21: =IF(OR(L21="",Y21=""),"",IF(Y21<L21,"Reduced by "&(L21-Y21)&" pts",IF(Y21=L21,"No Change","Increased by "&(Y21-L21)&" pts"))) -> No Change | AB21: =IF(Y21="","",Y21+(ROW()/10000000)) -> 9.0000021
A22: 17 | B22: PHC/NCDIMH | C22: 4. Program execution and delivery | D22: Delayed implementation of division projects | E22: If there are continued delays in project related activities, which may result in delayed implementation of planned activities which may result in organizational project and reputational risk and public negative communication about programme | F22: 1. Lack of intercenter teamwork and prioritization of activities 2. Delayed and non action on shared task and action points regarding projects. | G22: Project | H22: Possible | I22: =IFERROR(IF(H22="Unlikely",1,IF(H22="Possible",2,IF(H22="Likely",3,IF(H22="Almost Certain",4,IF(H22="Certain",5,""))))),"") -> 2 | J22: Moderate | K22: =IFERROR(IF(J22="Negligible",1,IF(J22="Minor",2,IF(J22="Moderate",3,IF(J22="Major",4,IF(J22="Critical",5,""))))),"") -> 3 | L22: =IF(OR(I22="",K22=""),"",I22*K22) -> 6 | M22: Improved Approval process and internal systems | O22: 45930 | P22: Open - Extended | Q22: PHC Centre Director, other Center directors and Executive Office | U22: =IF(L22="","",IF(L22<=4,"Low",IF(L22<=9,"Medium",IF(L22<=15,"High","Critical")))) -> Medium | W22: =IF(I22="","",MAX(1,I22-(IF(V22="Limited",1,IF(V22="Partial",2,IF(V22="Substantial",3,IF(V22="Highly Effective",4,0))))))) -> 2 | X22: =IF(K22="","",MAX(1,K22-ROUNDDOWN((IF(V22="Limited",1,IF(V22="Partial",2,IF(V22="Substantial",3,IF(V22="Highly Effective",4,0)))))/2,0))) -> 3 | Y22: =IF(OR(W22="",X22=""),"",W22*X22) -> 6 | Z22: =IF(Y22="","",IF(Y22<=4,"Low",IF(Y22<=9,"Medium",IF(Y22<=15,"High","Critical")))) -> Medium | AA22: =IF(OR(L22="",Y22=""),"",IF(Y22<L22,"Reduced by "&(L22-Y22)&" pts",IF(Y22=L22,"No Change","Increased by "&(Y22-L22)&" pts"))) -> No Change | AB22: =IF(Y22="","",Y22+(ROW()/10000000)) -> 6.0000022
A23: 18 | B23: EPR | C23: 2. Workforce sustainability and institutional capability | D23: Unstable contracts for 90% of the Division staff | E23: If the division continues to rely on more than 90% staff with unstable contract, then it faces a significant risk of operational disruption should the staff move away from Africa CDC. | F23: Lack of a diversified donor strategy – No structured plan to attract multiple donors for human resource funding. Inadequate resource mobilization capacity – No dedicated team/personnel to develop and execute funding strategies. Over-reliance on short-term project-based funding – Human resource costs are linked to time-bound donor projects. Absence of institutional core funding – The organization lacks a core budget to support staff independently of external donors. Weak donor relationship management – Insufficient engagement with other donors to expand the funding base. Organizational culture focused on program delivery over sustainability – Emphasis on outputs without strategic planning for long-term viability. | G23: Operational | H23: Likely | I23: =IFERROR(IF(H23="Unlikely",1,IF(H23="Possible",2,IF(H23="Likely",3,IF(H23="Almost Certain",4,IF(H23="Certain",5,""))))),"") -> 3 | J23: Critical | K23: =IFERROR(IF(J23="Negligible",1,IF(J23="Minor",2,IF(J23="Moderate",3,IF(J23="Major",4,IF(J23="Critical",5,""))))),"") -> 5 | L23: =IF(OR(I23="",K23=""),"",I23*K23) -> 15 | M23: -Provide a long duration contract, at least one year. - Ensure inclusion of HR in each project during grant proposal discussion | O23: 45930 | P23: Open - Extended | Q23: Organization wide, Head of division, HR, Partnership | U23: =IF(L23="","",IF(L23<=4,"Low",IF(L23<=9,"Medium",IF(L23<=15,"High","Critical")))) -> High | W23: =IF(I23="","",MAX(1,I23-(IF(V23="Limited",1,IF(V23="Partial",2,IF(V23="Substantial",3,IF(V23="Highly Effective",4,0))))))) -> 3 | X23: =IF(K23="","",MAX(1,K23-ROUNDDOWN((IF(V23="Limited",1,IF(V23="Partial",2,IF(V23="Substantial",3,IF(V23="Highly Effective",4,0)))))/2,0))) -> 5 | Y23: =IF(OR(W23="",X23=""),"",W23*X23) -> 15 | Z23: =IF(Y23="","",IF(Y23<=4,"Low",IF(Y23<=9,"Medium",IF(Y23<=15,"High","Critical")))) -> High | AA23: =IF(OR(L23="",Y23=""),"",IF(Y23<L23,"Reduced by "&(L23-Y23)&" pts",IF(Y23=L23,"No Change","Increased by "&(Y23-L23)&" pts"))) -> No Change | AB23: =IF(Y23="","",Y23+(ROW()/10000000)) -> 15.000002
A24: 19 | B24: EPR | C24: 4. Program execution and delivery | D24: Inadequate knowledge & awareness of perceived written procedures for the Division operations | E24: If staff have limited knowledge or unawareness of SOPs that govern the day-to-day division operations, then it faces a significant risk of non-compliance and reputation | F24: Lack of Awareness and Resistance to Change: staff may not fully understand the importance of SOPs and how they contribute to consistency and efficiency and then prefer informal workflows and resist documentation, fearing rigid processes Rapid Growth: The division has experienced rapid expansion since the period of Covid-19 (a lot initiatives, projects and processes have been introduced) and may struggle to formalize the processes. Limited Resources: Creating SOPs requires time, effort, and expertise, which may not be prioritized due to resource constraints. Over-Reliance on Individual Expertise: Preference to depend too much on the experience of key staff instead of formalizing best practices. Lack of Leadership Support: Without top management driving the need for SOPs, staff may not see their necessity. | G24: Operational | H24: Likely | I24: =IFERROR(IF(H24="Unlikely",1,IF(H24="Possible",2,IF(H24="Likely",3,IF(H24="Almost Certain",4,IF(H24="Certain",5,""))))),"") -> 3 | J24: Critical | K24: =IFERROR(IF(J24="Negligible",1,IF(J24="Minor",2,IF(J24="Moderate",3,IF(J24="Major",4,IF(J24="Critical",5,""))))),"") -> 5 | L24: =IF(OR(I24="",K24=""),"",I24*K24) -> 15 | M24: - Organize regular mentorship (awareness creation) on internal procedures - Put in place champions on some of routine operations (rwitting memo, reports…) | O24: 45930 | P24: Open - Extended | Q24: Heads of units, EPR | U24: =IF(L24="","",IF(L24<=4,"Low",IF(L24<=9,"Medium",IF(L24<=15,"High","Critical")))) -> High | W24: =IF(I24="","",MAX(1,I24-(IF(V24="Limited",1,IF(V24="Partial",2,IF(V24="Substantial",3,IF(V24="Highly Effective",4,0))))))) -> 3 | X24: =IF(K24="","",MAX(1,K24-ROUNDDOWN((IF(V24="Limited",1,IF(V24="Partial",2,IF(V24="Substantial",3,IF(V24="Highly Effective",4,0)))))/2,0))) -> 5 | Y24: =IF(OR(W24="",X24=""),"",W24*X24) -> 15 | Z24: =IF(Y24="","",IF(Y24<=4,"Low",IF(Y24<=9,"Medium",IF(Y24<=15,"High","Critical")))) -> High | AA24: =IF(OR(L24="",Y24=""),"",IF(Y24<L24,"Reduced by "&(L24-Y24)&" pts",IF(Y24=L24,"No Change","Increased by "&(Y24-L24)&" pts"))) -> No Change | AB24: =IF(Y24="","",Y24+(ROW()/10000000)) -> 15.000002
A25: 20 | B25: EPR | C25: 8. Integrity, compliance, and safeguarding | D25: Sexual Exploitation, Abuse and Harassment by Health emergency Responders (staffs, AVoHC RRT) during deplpyment for Health Emergency Response. | E25: If Health Emergenccy Responders commit SEA, SH during deployment, Africa CDC faces a significate reputational risks. | F25: Weak Enforcement of Policies: Gaps in implementation or enforcement of Africa CDC directives on SEAH prevention, may allow misconduct to persist. Power Imbalances: AVoHC responders operate in vulnerable communities where individuals may even prompt the responders to these kind of practices Cultural & Social Norms: In some African regions, deeply ingrained gender inequalities may contribute to tolerance or underreporting of SEAH incidents Reporting Mechanisms: Lack or limited access to safe reporting channels, preventing tthe victims from seeking justice. Failure to Monitor & Hold Perpetrators Accountable: Weak oversight and insufficient disciplinary measures can create an environment where misconduct goes unchecked | G25: Reputational | H25: Likely | I25: =IFERROR(IF(H25="Unlikely",1,IF(H25="Possible",2,IF(H25="Likely",3,IF(H25="Almost Certain",4,IF(H25="Certain",5,""))))),"") -> 3 | J25: Critical | K25: =IFERROR(IF(J25="Negligible",1,IF(J25="Minor",2,IF(J25="Moderate",3,IF(J25="Major",4,IF(J25="Critical",5,""))))),"") -> 5 | L25: =IF(OR(I25="",K25=""),"",I25*K25) -> 15 | M25: - Regular briefing on prevention of SEAH before deoloyment using WHO standars for example -Systematically ensure all responders sign and adhere to a code that explicitly prohibits SEAH. -Establish confidential mechanism for victims and witnesses to report misconduct safely. | O25: 45930 | P25: Open - Extended | Q25: AVoHC Program lead, HR, Legal | U25: =IF(L25="","",IF(L25<=4,"Low",IF(L25<=9,"Medium",IF(L25<=15,"High","Critical")))) -> High | W25: =IF(I25="","",MAX(1,I25-(IF(V25="Limited",1,IF(V25="Partial",2,IF(V25="Substantial",3,IF(V25="Highly Effective",4,0))))))) -> 3 | X25: =IF(K25="","",MAX(1,K25-ROUNDDOWN((IF(V25="Limited",1,IF(V25="Partial",2,IF(V25="Substantial",3,IF(V25="Highly Effective",4,0)))))/2,0))) -> 5 | Y25: =IF(OR(W25="",X25=""),"",W25*X25) -> 15 | Z25: =IF(Y25="","",IF(Y25<=4,"Low",IF(Y25<=9,"Medium",IF(Y25<=15,"High","Critical")))) -> High | AA25: =IF(OR(L25="",Y25=""),"",IF(Y25<L25,"Reduced by "&(L25-Y25)&" pts",IF(Y25=L25,"No Change","Increased by "&(Y25-L25)&" pts"))) -> No Change | AB25: =IF(Y25="","",Y25+(ROW()/10000000)) -> 15.000003
A26: 21 | B26: EPR | C26: 1. Sustainable financing and resource mobilization | D26: Insuficient fundings | E26: If the division does not have sufficient funds, if faces significant risk to not achieving the strategic goals/objectives | F26: Declining External Support: Official Development Assistance (ODA) to Africa has decreased by 70% in recent years, reducing financial resources for health security. Limited Domestic Investment: Few African Union Member States meet the Abuja target of allocating 15% of national budgets to healthcare, leading to reliance on external donors, and therefore a lot of request for assistance during health emeregencies Rising Health Emergencies: The continent continiouselly experiences an increase in public health emergencies, stretching available funds Lack of Sustainable Financing Models: Traditional funding mechanisms (mainly donors) are unpredictable, making it difficult to maintain consistent financial support. | G26: Strategic | H26: Certain | I26: =IFERROR(IF(H26="Unlikely",1,IF(H26="Possible",2,IF(H26="Likely",3,IF(H26="Almost Certain",4,IF(H26="Certain",5,""))))),"") -> 5 | J26: Critical | K26: =IFERROR(IF(J26="Negligible",1,IF(J26="Minor",2,IF(J26="Moderate",3,IF(J26="Major",4,IF(J26="Critical",5,""))))),"") -> 5 | L26: =IF(OR(I26="",K26=""),"",I26*K26) -> 25 | M26: -Ensure efficient management of existing funds using data driven allocation (prioritzation and integration) - Mobilize more ressources based on strategic vision and clear goal and objectives - At least have two or tree partners engaged and incoperated in our planning early enough (example ECDC, UK-HSA) | O26: 45930 | P26: Open - Extended | Q26: Head of division, Head of units, Partnership | U26: =IF(L26="","",IF(L26<=4,"Low",IF(L26<=9,"Medium",IF(L26<=15,"High","Critical")))) -> Critical | W26: =IF(I26="","",MAX(1,I26-(IF(V26="Limited",1,IF(V26="Partial",2,IF(V26="Substantial",3,IF(V26="Highly Effective",4,0))))))) -> 5 | X26: =IF(K26="","",MAX(1,K26-ROUNDDOWN((IF(V26="Limited",1,IF(V26="Partial",2,IF(V26="Substantial",3,IF(V26="Highly Effective",4,0)))))/2,0))) -> 5 | Y26: =IF(OR(W26="",X26=""),"",W26*X26) -> 25 | Z26: =IF(Y26="","",IF(Y26<=4,"Low",IF(Y26<=9,"Medium",IF(Y26<=15,"High","Critical")))) -> Critical | AA26: =IF(OR(L26="",Y26=""),"",IF(Y26<L26,"Reduced by "&(L26-Y26)&" pts",IF(Y26=L26,"No Change","Increased by "&(Y26-L26)&" pts"))) -> No Change | AB26: =IF(Y26="","",Y26+(ROW()/10000000)) -> 25.000003
A27: 22 | B27: EPR | C27: 9. Emergency readiness, duty of care, and biosafety/biosecurity | D27: Deployment of AVoHC responders to an outbreak without medical or insurance cover | E27: If AVoHC responder falls sick, gets infected by the disease they are responding to or even dies, this may expose Africa CDC to legal proceedures that may turnish the reputation of the organization | F27: -Reactive deployment operations: In fast-moving outbreaks, responders may be deployed quickly without completion of all administrative processes, including insurance arrangements. - Short duration of deployment: Many insurance companies require a minimum contract period (often 12 months) for coverage, while AVoHC deployments typically last only three months. This mismatch makes it difficult to secure appropriate insurance plans for short-term responders. | G27: Public Health Emergency Response | H27: Almost Certain | I27: =IFERROR(IF(H27="Unlikely",1,IF(H27="Possible",2,IF(H27="Likely",3,IF(H27="Almost Certain",4,IF(H27="Certain",5,""))))),"") -> 4 | J27: Critical | K27: =IFERROR(IF(J27="Negligible",1,IF(J27="Minor",2,IF(J27="Moderate",3,IF(J27="Major",4,IF(J27="Critical",5,""))))),"") -> 5 | L27: =IF(OR(I27="",K27=""),"",I27*K27) -> 20 | M27: -Identify the mechanism for systematically provide health insurance before deployment - Establish a stand-by framework agreement with health issurance | O27: 45930 | P27: Open - Extended | Q27: AVoHC Program lead, HR | U27: =IF(L27="","",IF(L27<=4,"Low",IF(L27<=9,"Medium",IF(L27<=15,"High","Critical")))) -> Critical | W27: =IF(I27="","",MAX(1,I27-(IF(V27="Limited",1,IF(V27="Partial",2,IF(V27="Substantial",3,IF(V27="Highly Effective",4,0))))))) -> 4 | X27: =IF(K27="","",MAX(1,K27-ROUNDDOWN((IF(V27="Limited",1,IF(V27="Partial",2,IF(V27="Substantial",3,IF(V27="Highly Effective",4,0)))))/2,0))) -> 5 | Y27: =IF(OR(W27="",X27=""),"",W27*X27) -> 20 | Z27: =IF(Y27="","",IF(Y27<=4,"Low",IF(Y27<=9,"Medium",IF(Y27<=15,"High","Critical")))) -> Critical | AA27: =IF(OR(L27="",Y27=""),"",IF(Y27<L27,"Reduced by "&(L27-Y27)&" pts",IF(Y27=L27,"No Change","Increased by "&(Y27-L27)&" pts"))) -> No Change | AB27: =IF(Y27="","",Y27+(ROW()/10000000)) -> 20.000003
A28: 23 | B28: EPR | C28: 9. Emergency readiness, duty of care, and biosafety/biosecurity | D28: Emergency Response in a complexe humanitarian context | E28: If Africa CDC deploys experts in a complex humanitarian setting where disease outbreaks are reported to provide live saving response activities, it can make it difficult for Africa CDC to have meaningful presence on the ground. | F28: -Limited/lack of collaboration with AUC Peace and Security department -There is no Travel Security Information File for Africa CDC staff travelling to MS | G28: Public Health Emergency Response | H28: Possible | I28: =IFERROR(IF(H28="Unlikely",1,IF(H28="Possible",2,IF(H28="Likely",3,IF(H28="Almost Certain",4,IF(H28="Certain",5,""))))),"") -> 2 | J28: Critical | K28: =IFERROR(IF(J28="Negligible",1,IF(J28="Minor",2,IF(J28="Moderate",3,IF(J28="Major",4,IF(J28="Critical",5,""))))),"") -> 5 | L28: =IF(OR(I28="",K28=""),"",I28*K28) -> 10 | M28: -Joint deployment with AUC Peace and security department - Getting security clearence before deploying in humanitarian seeting | O28: 45930 | P28: Open - Extended | Q28: PHEOC | U28: =IF(L28="","",IF(L28<=4,"Low",IF(L28<=9,"Medium",IF(L28<=15,"High","Critical")))) -> High | W28: =IF(I28="","",MAX(1,I28-(IF(V28="Limited",1,IF(V28="Partial",2,IF(V28="Substantial",3,IF(V28="Highly Effective",4,0))))))) -> 2 | X28: =IF(K28="","",MAX(1,K28-ROUNDDOWN((IF(V28="Limited",1,IF(V28="Partial",2,IF(V28="Substantial",3,IF(V28="Highly Effective",4,0)))))/2,0))) -> 5 | Y28: =IF(OR(W28="",X28=""),"",W28*X28) -> 10 | Z28: =IF(Y28="","",IF(Y28<=4,"Low",IF(Y28<=9,"Medium",IF(Y28<=15,"High","Critical")))) -> High | AA28: =IF(OR(L28="",Y28=""),"",IF(Y28<L28,"Reduced by "&(L28-Y28)&" pts",IF(Y28=L28,"No Change","Increased by "&(Y28-L28)&" pts"))) -> No Change | AB28: =IF(Y28="","",Y28+(ROW()/10000000)) -> 10.000003
A29: 24 | B29: EPR | C29: 9. Emergency readiness, duty of care, and biosafety/biosecurity | D29: Cumbersome internal approval process and late response to MS requests | E29: If the division delays or fails to response timely of the request made by the MS or providing support especially during health emergencies, that crerate a lack of trust from the MS which in turn can cause a significant reputational risk | F29: -Change of priorities based on PHE occurency and dynamics - Limited funds for emergency response interventions - Delays in getting the timely internal approvals which cause unnecessary delays in responding to emergenciew | G29: Public Health Emergency Response | H29: Likely | I29: =IFERROR(IF(H29="Unlikely",1,IF(H29="Possible",2,IF(H29="Likely",3,IF(H29="Almost Certain",4,IF(H29="Certain",5,""))))),"") -> 3 | J29: Critical | K29: =IFERROR(IF(J29="Negligible",1,IF(J29="Minor",2,IF(J29="Moderate",3,IF(J29="Major",4,IF(J29="Critical",5,""))))),"") -> 5 | L29: =IF(OR(I29="",K29=""),"",I29*K29) -> 15 | M29: -Always make sure the availability of funds before any commitment of support to MS - Increase funding for emergency response | O29: 45930 | P29: Open - Extended | Q29: Executive Office, HoD, Heads of Units, Partnership division | U29: =IF(L29="","",IF(L29<=4,"Low",IF(L29<=9,"Medium",IF(L29<=15,"High","Critical")))) -> High | W29: =IF(I29="","",MAX(1,I29-(IF(V29="Limited",1,IF(V29="Partial",2,IF(V29="Substantial",3,IF(V29="Highly Effective",4,0))))))) -> 3 | X29: =IF(K29="","",MAX(1,K29-ROUNDDOWN((IF(V29="Limited",1,IF(V29="Partial",2,IF(V29="Substantial",3,IF(V29="Highly Effective",4,0)))))/2,0))) -> 5 | Y29: =IF(OR(W29="",X29=""),"",W29*X29) -> 15 | Z29: =IF(Y29="","",IF(Y29<=4,"Low",IF(Y29<=9,"Medium",IF(Y29<=15,"High","Critical")))) -> High | AA29: =IF(OR(L29="",Y29=""),"",IF(Y29<L29,"Reduced by "&(L29-Y29)&" pts",IF(Y29=L29,"No Change","Increased by "&(Y29-L29)&" pts"))) -> No Change | AB29: =IF(Y29="","",Y29+(ROW()/10000000)) -> 15.000003
A30: 25 | B30: Lab | C30: 9. Emergency readiness, duty of care, and biosafety/biosecurity | D30: Limited implementation of biosafety and biosecurity regulations across AU Member States | E30: Increased risk of accidental or intentional release of biological agents; reputational damage to Africa CDC; hindered regional preparedness. | F30: Lack of political support from AU Member States. Lack of technical assistance and resource mobilization for implementation. | G30: Strategic | H30: Almost Certain | I30: =IFERROR(IF(H30="Unlikely",1,IF(H30="Possible",2,IF(H30="Likely",3,IF(H30="Almost Certain",4,IF(H30="Certain",5,""))))),"") -> 4 | J30: Critical | K30: =IFERROR(IF(J30="Negligible",1,IF(J30="Minor",2,IF(J30="Moderate",3,IF(J30="Major",4,IF(J30="Critical",5,""))))),"") -> 5 | L30: =IF(OR(I30="",K30=""),"",I30*K30) -> 20 | M30: Promote harmonized regulatory frameworks. Build capacity in biosafety/biosecurity at national levels. | O30: 45930 | P30: Open - Extended | Q30: Africa CDC - Lab | U30: =IF(L30="","",IF(L30<=4,"Low",IF(L30<=9,"Medium",IF(L30<=15,"High","Critical")))) -> Critical | W30: =IF(I30="","",MAX(1,I30-(IF(V30="Limited",1,IF(V30="Partial",2,IF(V30="Substantial",3,IF(V30="Highly Effective",4,0))))))) -> 4 | X30: =IF(K30="","",MAX(1,K30-ROUNDDOWN((IF(V30="Limited",1,IF(V30="Partial",2,IF(V30="Substantial",3,IF(V30="Highly Effective",4,0)))))/2,0))) -> 5 | Y30: =IF(OR(W30="",X30=""),"",W30*X30) -> 20 | Z30: =IF(Y30="","",IF(Y30<=4,"Low",IF(Y30<=9,"Medium",IF(Y30<=15,"High","Critical")))) -> Critical | AA30: =IF(OR(L30="",Y30=""),"",IF(Y30<L30,"Reduced by "&(L30-Y30)&" pts",IF(Y30=L30,"No Change","Increased by "&(Y30-L30)&" pts"))) -> No Change | AB30: =IF(Y30="","",Y30+(ROW()/10000000)) -> 20.000003
A31: 26 | B31: Lab | C31: 7. Data governance and management reporting | D31: Data sovereignty, security and sharing issues among Member States | E31: Delayed or fragmented genomic surveillance; ethical and legal disputes. | F31: lack of investment in the Member State I n terms of genomic infrastructure. | G31: Operational | H31: Possible | I31: =IFERROR(IF(H31="Unlikely",1,IF(H31="Possible",2,IF(H31="Likely",3,IF(H31="Almost Certain",4,IF(H31="Certain",5,""))))),"") -> 2 | J31: Major | K31: =IFERROR(IF(J31="Negligible",1,IF(J31="Minor",2,IF(J31="Moderate",3,IF(J31="Major",4,IF(J31="Critical",5,""))))),"") -> 4 | L31: =IF(OR(I31="",K31=""),"",I31*K31) -> 8 | M31: Develop AU-wide data governance policies. Promote ethical, legal and social frameworks. Strengthen in-country capacity for data storage and analysis | O31: 45930 | P31: Open - Extended | Q31: Africa CDC - Lab | U31: =IF(L31="","",IF(L31<=4,"Low",IF(L31<=9,"Medium",IF(L31<=15,"High","Critical")))) -> Medium | W31: =IF(I31="","",MAX(1,I31-(IF(V31="Limited",1,IF(V31="Partial",2,IF(V31="Substantial",3,IF(V31="Highly Effective",4,0))))))) -> 2 | X31: =IF(K31="","",MAX(1,K31-ROUNDDOWN((IF(V31="Limited",1,IF(V31="Partial",2,IF(V31="Substantial",3,IF(V31="Highly Effective",4,0)))))/2,0))) -> 4 | Y31: =IF(OR(W31="",X31=""),"",W31*X31) -> 8 | Z31: =IF(Y31="","",IF(Y31<=4,"Low",IF(Y31<=9,"Medium",IF(Y31<=15,"High","Critical")))) -> Medium | AA31: =IF(OR(L31="",Y31=""),"",IF(Y31<L31,"Reduced by "&(L31-Y31)&" pts",IF(Y31=L31,"No Change","Increased by "&(Y31-L31)&" pts"))) -> No Change | AB31: =IF(Y31="","",Y31+(ROW()/10000000)) -> 8.0000031
... A37: 32 | B37: SDI | C37: 5. Country, partner, and geopolitical context | D37: Changing surveillance priorities of MS e.g routine program vs emergency response | E37: The surveillance priorities of the Member states keep changing during the implemantation year of Africa CDC. For example planned routine surveillance activites are often disrupted during outbreak/ emergency response. This in turn leads to data gaps, reduced program effectivenes and delayed detection | F37: Public health emergency events such as outbreaks requiring urgent attention. Reallocation of limited resources Donor-driven priorities Change of leadership with in the ministries responsible for health in MS | G37: Strategic | H37: Likely | I37: =IFERROR(IF(H37="Unlikely",1,IF(H37="Possible",2,IF(H37="Likely",3,IF(H37="Almost Certain",4,IF(H37="Certain",5,""))))),"") -> 3 | J37: Major | K37: =IFERROR(IF(J37="Negligible",1,IF(J37="Minor",2,IF(J37="Moderate",3,IF(J37="Major",4,IF(J37="Critical",5,""))))),"") -> 4 | L37: =IF(OR(I37="",K37=""),"",I37*K37) -> 12 | M37: Developing flexible operational plans to always cater for emergencies Advocate for integrated surveillance systems and employ a one health approach Develop early warning systems for resource shifts | O37: 45992 | P37: Open - Extended | Q37: Senior leadership Head of Division Head of Units | U37: =IF(L37="","",IF(L37<=4,"Low",IF(L37<=9,"Medium",IF(L37<=15,"High","Critical")))) -> High | W37: =IF(I37="","",MAX(1,I37-(IF(V37="Limited",1,IF(V37="Partial",2,IF(V37="Substantial",3,IF(V37="Highly Effective",4,0))))))) -> 3 | X37: =IF(K37="","",MAX(1,K37-ROUNDDOWN((IF(V37="Limited",1,IF(V37="Partial",2,IF(V37="Substantial",3,IF(V37="Highly Effective",4,0)))))/2,0))) -> 4 | Y37: =IF(OR(W37="",X37=""),"",W37*X37) -> 12 | Z37: =IF(Y37="","",IF(Y37<=4,"Low",IF(Y37<=9,"Medium",IF(Y37<=15,"High","Critical")))) -> High | AA37: =IF(OR(L37="",Y37=""),"",IF(Y37<L37,"Reduced by "&(L37-Y37)&" pts",IF(Y37=L37,"No Change","Increased by "&(Y37-L37)&" pts"))) -> No Change | AB37: =IF(Y37="","",Y37+(ROW()/10000000)) -> 12.000004
A38: 33 | B38: SDI | C38: 7. Data governance and management reporting | D38: Lack of Data sharing with MS | E38: Data sharing agreement has been an ongoing effort to secure MS commitment to share data regularly with Africa CDC, however the progress is slow | F38: Public health emergency events such as outbreaks are sensitive to share data for both political and economic reason low confidence and trust to the Africa CDC systems for protection of the data lack of visible support and investiment in the data systems of MS to ask for data sharing tangeble insentive to MS for sharing their data | G38: Strategic | H38: Almost Certain | I38: =IFERROR(IF(H38="Unlikely",1,IF(H38="Possible",2,IF(H38="Likely",3,IF(H38="Almost Certain",4,IF(H38="Certain",5,""))))),"") -> 4 | J38: Major | K38: =IFERROR(IF(J38="Negligible",1,IF(J38="Minor",2,IF(J38="Moderate",3,IF(J38="Major",4,IF(J38="Critical",5,""))))),"") -> 4 | L38: =IF(OR(I38="",K38=""),"",I38*K38) -> 16 | O38: 45930 | P38: Open - Extended | Q38: Senior leadership Legal Division Head of Division Head of Units | U38: =IF(L38="","",IF(L38<=4,"Low",IF(L38<=9,"Medium",IF(L38<=15,"High","Critical")))) -> Critical | W38: =IF(I38="","",MAX(1,I38-(IF(V38="Limited",1,IF(V38="Partial",2,IF(V38="Substantial",3,IF(V38="Highly Effective",4,0))))))) -> 4 | X38: =IF(K38="","",MAX(1,K38-ROUNDDOWN((IF(V38="Limited",1,IF(V38="Partial",2,IF(V38="Substantial",3,IF(V38="Highly Effective",4,0)))))/2,0))) -> 4 | Y38: =IF(OR(W38="",X38=""),"",W38*X38) -> 16 | Z38: =IF(Y38="","",IF(Y38<=4,"Low",IF(Y38<=9,"Medium",IF(Y38<=15,"High","Critical")))) -> Critical | AA38: =IF(OR(L38="",Y38=""),"",IF(Y38<L38,"Reduced by "&(L38-Y38)&" pts",IF(Y38=L38,"No Change","Increased by "&(Y38-L38)&" pts"))) -> No Change | AB38: =IF(Y38="","",Y38+(ROW()/10000000)) -> 16.000004
A39: 34 | B39: SDI | C39: 2. Workforce sustainability and institutional capability | D39: Limited workforce ;for a highly demanding Division mandate | E39: Limited workforce capacity may hinder the Division’s ability to deliver on its complex and growing mandate, causing delays, reduced quality, or missed strategic opportunities | F39: Budgetary constraints limiting hiring Lengthy recruitment processes Expansion of mandate without matching resource increases | G39: Strategic | H39: Certain | I39: =IFERROR(IF(H39="Unlikely",1,IF(H39="Possible",2,IF(H39="Likely",3,IF(H39="Almost Certain",4,IF(H39="Certain",5,""))))),"") -> 5 | J39: Critical | K39: =IFERROR(IF(J39="Negligible",1,IF(J39="Minor",2,IF(J39="Moderate",3,IF(J39="Major",4,IF(J39="Critical",5,""))))),"") -> 5 | L39: =IF(OR(I39="",K39=""),"",I39*K39) -> 25 | M39: Advocate for increased staffing and budget allocations Prioritize tasks based on needs assessment Strengthen partnerships to support workload | O39: 45930 | P39: Open - Extended | Q39: Head of Division HR Senior Leadership Head of Units | U39: =IF(L39="","",IF(L39<=4,"Low",IF(L39<=9,"Medium",IF(L39<=15,"High","Critical")))) -> Critical | W39: =IF(I39="","",MAX(1,I39-(IF(V39="Limited",1,IF(V39="Partial",2,IF(V39="Substantial",3,IF(V39="Highly Effective",4,0))))))) -> 5 | X39: =IF(K39="","",MAX(1,K39-ROUNDDOWN((IF(V39="Limited",1,IF(V39="Partial",2,IF(V39="Substantial",3,IF(V39="Highly Effective",4,0)))))/2,0))) -> 5 | Y39: =IF(OR(W39="",X39=""),"",W39*X39) -> 25 | Z39: =IF(Y39="","",IF(Y39<=4,"Low",IF(Y39<=9,"Medium",IF(Y39<=15,"High","Critical")))) -> Critical | AA39: =IF(OR(L39="",Y39=""),"",IF(Y39<L39,"Reduced by "&(L39-Y39)&" pts",IF(Y39=L39,"No Change","Increased by "&(Y39-L39)&" pts"))) -> No Change | AB39: =IF(Y39="","",Y39+(ROW()/10000000)) -> 25.000004
